{
  "comments": [
    {
      "unresolved": false,
      "key": {
        "uuid": "9f95232f_8dd391da",
        "filename": "/PATCHSET_LEVEL",
        "patchSetId": 1
      },
      "lineNbr": 0,
      "author": {
        "id": 1015563
      },
      "writtenOn": "2021-08-21T00:15:50Z",
      "side": 1,
      "message": "recheck tripleo-overcloud-osp16.1-ipv4\n\nAFICT this job failed due to an unrelated issue:\n\nhttp://rhos-ci-logs.lab.eng.tlv2.redhat.com/logs/rcj/gate-infrared-tripleo-overcloud-osp16.1-ipv4/1277/undercloud-0/home/stack/undercloud_install.log.gz\n\n```\n  \"DEBUG:tripleo_common.image.image_uploader:https://rhos-qe-mirror-rdu2.usersys.redhat.com:5002/v2/ status code 502\", \"ERROR:root:Image prepare failed: 502 Server Error: Bad Gateway for url: https://rhos-qe-mirror-rdu2.usersys.redhat.com:5002/v2/\", \"concurrent.futures.process._RemoteTraceback: \", \"\\\"\\\"\\\"\", \"Traceback (most recent call last):\", \"  File \\\"/usr/lib64/python3.6/concurrent/futures/process.py\\\", line 175, in _process_worker\", \"    r \u003d call_item.fn(*call_item.args, **call_item.kwargs)\", \"  File \\\"/usr/lib64/python3.6/concurrent/futures/process.py\\\", line 153, in _process_chunk\", \"    return [fn(*args) for args in chunk]\", \"  File \\\"/usr/lib64/python3.6/concurrent/futures/process.py\\\", line 153, in \u003clistcomp\u003e\", \"    return [fn(*args) for args in chunk]\", \"  File \\\"/usr/lib/python3.6/site-packages/tripleo_common/image/image_uploader.py\\\", line 2576, in upload_task\", \"    return uploader.upload_image(task)\", \"  File \\\"/usr/lib/python3.6/site-packages/tripleo_common/image/image_uploader.py\\\", line 1530, in upload_image\", \"    password\u003dsource_password\", \"  File \\\"/usr/lib/python3.6/site-packages/tenacity/__init__.py\\\", line 292, in wrapped_f\", \"    return self.call(f, *args, **kw)\", \"  File \\\"/usr/lib/python3.6/site-packages/tenacity/__init__.py\\\", line 358, in call\", \"    do \u003d self.iter(retry_state\u003dretry_state)\", \"  File \\\"/usr/lib/python3.6/site-packages/tenacity/__init__.py\\\", line 331, in iter\", \"    raise retry_exc.reraise()\", \"  File \\\"/usr/lib/python3.6/site-packages/tenacity/__init__.py\\\", line 167, in reraise\", \"    raise self.last_attempt.result()\", \"  File \\\"/usr/lib64/python3.6/concurrent/futures/_base.py\\\", line 425, in result\", \"    return self.__get_result()\", \"  File \\\"/usr/lib64/python3.6/concurrent/futures/_base.py\\\", line 384, in __get_result\", \"    raise self._exception\", \"  File \\\"/usr/lib/python3.6/site-packages/tenacity/__init__.py\\\", line 361, in call\", \"    result \u003d fn(*args, **kwargs)\", \"  File \\\"/usr/lib/python3.6/site-packages/tripleo_common/image/image_uploader.py\\\", line 665, in authenticate\", \"    r.raise_for_status()\", \"  File \\\"/usr/lib/python3.6/site-packages/requests/models.py\\\", line 940, in raise_for_status\", \"    raise HTTPError(http_error_msg, response\u003dself)\", \"requests.exceptions.HTTPError: 502 Server Error: Bad Gateway for url: https://rhos-qe-mirror-rdu2.usersys.redhat.com:5002/v2/\", \"\\\"\\\"\\\"\", \"\", \"The above exception was the direct cause of the following exception:\", \"\", \"Traceback (most recent call last):\", \"  File \\\"/usr/bin/tripleo-container-image-prepare\\\", line 138, in \u003cmodule\u003e\", \"    lock\u003dlock)\", \"  File \\\"/usr/lib/python3.6/site-packages/tripleo_common/image/kolla_builder.py\\\", line 241, in container_images_prepare_multi\", \"    uploader.upload()\", \"  File \\\"/usr/lib/python3.6/site-packages/tripleo_common/image/image_uploader.py\\\", line 506, in upload\", \"    uploader.run_tasks()\", \"  File \\\"/usr/lib/python3.6/site-packages/tripleo_common/image/image_uploader.py\\\", line 2518, in run_tasks\", \"    for result in p.map(upload_task, self.upload_tasks):\", \"  File \\\"/usr/lib64/python3.6/concurrent/futures/process.py\\\", line 366, in _chain_from_iterable_of_lists\", \"    for element in iterable:\", \"  File \\\"/usr/lib64/python3.6/concurrent/futures/_base.py\\\", line 586, in result_iterator\", \"    yield fs.pop().result()\", \"  File \\\"/usr/lib64/python3.6/concurrent/futures/_base.py\\\", line 432, in result\", \"    return self.__get_result()\", \"  File \\\"/usr/lib64/python3.6/concurrent/futures/_base.py\\\", line 384, in __get_result\", \"    raise self._exception\", \"requests.exceptions.HTTPError: 502 Server Error: Bad Gateway for url: https://rhos-qe-mirror-rdu2.usersys.redhat.com:5002/v2/\"], \"stdout\": \"\", \"stdout_lines\": []}\n```",
      "revId": "31b42c542adf95e1f68d3ad36d8bea6316ddc660",
      "serverId": "d5d70762-12d0-45a1-890d-524b12d3f735"
    }
  ]
}